Workbook

Sheet Tracker
E2: P0, P1, P2, P3
C4: Page | D4: Bugs Logged | E4: Resolved | F4: Open | G4: Hold
B5: PVT | C5: Homepage | D5: {=SUMPRODUCT(('Home Page'!$G$2:$G$799="PVT") * ('Home Page'!$A$2:$A$799<>"") * (ISNUMBER(SEARCH('Home Page'!$C$2:$C$799, $E$2))))} -> 49 | E5: {=SUMPRODUCT(('Home Page'!$G$2:$G$799="PVT") * ('Home Page'!$Q$2:$Q$799="Resolved") * (ISNUMBER(SEARCH('Home Page'!$C$2:$C$799, $E$2))))} -> 20 | F5: {=SUMPRODUCT(('Home Page'!$G$2:$G$799="PVT") * (('Home Page'!$Q$2:$Q$799="Open") + ('Home Page'!$Q$2:$Q$799="Reopened")) * (ISNUMBER(SEARCH('Home Page'!$C$2:$C$799, $E$2))))} -> 28 | G5: {=SUMPRODUCT(('Home Page'!$G$2:$G$799="PVT") * ('Home Page'!$Q$2:$Q$799="Hold") * (ISNUMBER(SEARCH('Home Page'!$C$2:$C$799, $E$2))))} -> 1
C6: Product | D6: {=SUMPRODUCT(('Product Details Page'!$G$2:$G$800="PVT") * ('Product Details Page'!$A$2:$A$800<>"") * (ISNUMBER(SEARCH('Product Details Page'!$C$2:$C$800, $E$2)))) + SUMPRODUCT(('Credit Card Pages'!$F$2:$F$800="PVT") * ('Credit Card Pages'!$A$2:$A$800<>"") * (ISNUMBER(SEARCH('Credit Card Pages'!$C$2:$C$800, $E$2))))} -> 57 | E6: {=SUMPRODUCT(('Product Details Page'!$G$2:$G$800="PVT") * ('Product Details Page'!$Q$2:$Q$800="Resolved") * (ISNUMBER(SEARCH('Product Details Page'!$C$2:$C$800, $E$2)))) + SUMPRODUCT(('Credit Card Pages'!$F$2:$F$800="PVT") * ('Credit Card Pages'!$R$2:$R$800="Resolved") * (ISNUMBER(SEARCH('Credit Card Pages'!$C$2:$C$800, $E$2))))} -> 34 | F6: {=SUMPRODUCT(('Product Details Page'!$G$2:$G$800="PVT") * (('Product Details Page'!$Q$2:$Q$800="Open") + ('Product Details Page'!$Q$2:$Q$800="Reopened")) * (ISNUMBER(SEARCH('Product Details Page'!$C$2:$C$800, $E$2)))) + SUMPRODUCT(('Credit Card Pages'!$F$2:$F$800="PVT") * (('Credit Card Pages'!$R$2:$R$800="Open") + ('Credit Card Pages'!$R$2:$R$800="Reopened")) * (ISNUMBER(SEARCH('Credit Card Pages'!$C$2:$C$800, $E$2))))} -> 23 | G6: {=SUMPRODUCT(('Product Details Page'!$G$2:$G$800="PVT") * ('Product Details Page'!$Q$2:$Q$800="Hold") * (ISNUMBER(SEARCH('Product Details Page'!$C$2:$C$800, $E$2)))) + SUMPRODUCT(('Credit Card Pages'!$F$2:$F$800="PVT") * ('Credit Card Pages'!$R$2:$R$800="Hold") * (ISNUMBER(SEARCH('Credit Card Pages'!$C$2:$C$800, $E$2))))} -> 0
C7: Catalogue | D7: {=SUMPRODUCT(('Catalogue Page'!$G$2:$G$800="PVT") * ('Catalogue Page'!$A$2:$A$800<>"") * (ISNUMBER(SEARCH('Catalogue Page'!$C$2:$C$800, $E$2))))} -> 69 | E7: {=SUMPRODUCT(('Catalogue Page'!$G$2:$G$800="PVT") * ('Catalogue Page'!$Q$2:$Q$800="Resolved") * (ISNUMBER(SEARCH('Catalogue Page'!$C$2:$C$800, $E$2))))} -> 30 | F7: {=SUMPRODUCT(('Catalogue Page'!$G$2:$G$800="PVT") * (('Catalogue Page'!$Q$2:$Q$800="Open") + ('Catalogue Page'!$Q$2:$Q$800="Reopened")) * (ISNUMBER(SEARCH('Catalogue Page'!$C$2:$C$800, $E$2))))} -> 39 | G7: {=SUMPRODUCT(('Catalogue Page'!$G$2:$G$800="PVT") * ('Catalogue Page'!$Q$2:$Q$800="Hold") * (ISNUMBER(SEARCH('Catalogue Page'!$C$2:$C$800, $E$2))))} -> 0
C8: Header - Footer | D8: {=SUMPRODUCT(('Header & Footer'!$F$2:$F$800="PVT") * ('Header & Footer'!$A$2:$A$800<>"") * (ISNUMBER(SEARCH('Header & Footer'!$C$2:$C$800, $E$2))))} -> 16 | E8: {=SUMPRODUCT(('Header & Footer'!$F$2:$F$799="PVT") * ('Header & Footer'!$R$2:$R$799="Resolved") * (ISNUMBER(SEARCH('Header & Footer'!$C$2:$C$799, $E$2))))} -> 11 | F8: {=SUMPRODUCT(('Header & Footer'!$F$2:$F$799="PVT") * (('Header & Footer'!$R$2:$R$799="Open") + ('Header & Footer'!$R$2:$R$799="Reopened")) * (ISNUMBER(SEARCH('Header & Footer'!$C$2:$C$799, $E$2))))} -> 5 | G8: {=SUMPRODUCT(('Header & Footer'!$F$2:$F$799="PVT") * ('Header & Footer'!$R$2:$R$799="Hold") * (ISNUMBER(SEARCH('Header & Footer'!$C$2:$C$799, $E$2))))} -> 0
C9: Total | D9: =SUM(D5:D8) -> 191 | E9: =SUM(E5:E8) -> 95 | F9: =SUM(F5:F8) -> 95 | G9: =SUM(G5:G8) -> 1
B11: UAT | C11: Homepage | D11: {=SUMPRODUCT(('Home Page'!$G$2:$G$799="UAT") * ('Home Page'!$A$2:$A$799<>"") * (ISNUMBER(SEARCH('Home Page'!$C$2:$C$799, $E$2))))} -> 51 | E11: {=SUMPRODUCT(('Home Page'!$G$2:$G$799="UAT") * ('Home Page'!$Q$2:$Q$799="Resolved") * (ISNUMBER(SEARCH('Home Page'!$C$2:$C$799, $E$2))))} -> 25 | F11: {=SUMPRODUCT(('Home Page'!$G$2:$G$799="UAT") * (('Home Page'!$Q$2:$Q$799="Open") + ('Home Page'!$Q$2:$Q$799="Reopened")) * (ISNUMBER(SEARCH('Home Page'!$C$2:$C$799, $E$2))))} -> 5 | G11: {=SUMPRODUCT(('Home Page'!$G$2:$G$799="UAT") * ('Home Page'!$Q$2:$Q$799="Hold") * (ISNUMBER(SEARCH('Home Page'!$C$2:$C$799, $E$2))))} -> 21
C12: Product | D12: {=SUMPRODUCT(('Product Details Page'!$G$2:$G$800="UAT") * ('Product Details Page'!$A$2:$A$800<>"") * (ISNUMBER(SEARCH('Product Details Page'!$C$2:$C$800, $E$2)))) + SUMPRODUCT(('Credit Card Pages'!$F$2:$F$800="UAT") * ('Credit Card Pages'!$A$2:$A$800<>"") * (ISNUMBER(SEARCH('Credit Card Pages'!$C$2:$C$800, $E$2))))} -> 281 | E12: {=SUMPRODUCT(('Product Details Page'!$G$2:$G$800="UAT") * ('Product Details Page'!$Q$2:$Q$800="Resolved") * (ISNUMBER(SEARCH('Product Details Page'!$C$2:$C$800, $E$2)))) + SUMPRODUCT(('Credit Card Pages'!$F$2:$F$800="UAT") * ('Credit Card Pages'!$R$2:$R$800="Resolved") * (ISNUMBER(SEARCH('Credit Card Pages'!$C$2:$C$800, $E$2))))} -> 239 | F12: {=SUMPRODUCT(('Product Details Page'!$G$2:$G$800="UAT") * (('Product Details Page'!$Q$2:$Q$800="Open") + ('Product Details Page'!$Q$2:$Q$800="Reopened")) * (ISNUMBER(SEARCH('Product Details Page'!$C$2:$C$800, $E$2)))) + SUMPRODUCT(('Credit Card Pages'!$F$2:$F$800="UAT") * (('Credit Card Pages'!$R$2:$R$800="Open") + ('Credit Card Pages'!$R$2:$R$800="Reopened")) * (ISNUMBER(SEARCH('Credit Card Pages'!$C$2:$C$800, $E$2))))} -> 27 | G12: {=SUMPRODUCT(('Product Details Page'!$G$2:$G$800="UAT") * ('Product Details Page'!$Q$2:$Q$800="Hold") * (ISNUMBER(SEARCH('Product Details Page'!$C$2:$C$800, $E$2)))) + SUMPRODUCT(('Credit Card Pages'!$F$2:$F$800="UAT") * ('Credit Card Pages'!$R$2:$R$800="Hold") * (ISNUMBER(SEARCH('Credit Card Pages'!$C$2:$C$800, $E$2))))} -> 15
C13: Catalogue | D13: {=SUMPRODUCT(('Catalogue Page'!$G$2:$G$800="UAT") * ('Catalogue Page'!$A$2:$A$800<>"") * (ISNUMBER(SEARCH('Catalogue Page'!$C$2:$C$800, $E$2))))} -> 40 | E13: {=SUMPRODUCT(('Catalogue Page'!$G$2:$G$800="UAT") * ('Catalogue Page'!$Q$2:$Q$800="Resolved") * (ISNUMBER(SEARCH('Catalogue Page'!$C$2:$C$800, $E$2))))} -> 19 | F13: {=SUMPRODUCT(('Catalogue Page'!$G$2:$G$800="UAT") * (('Catalogue Page'!$Q$2:$Q$800="Open") + ('Catalogue Page'!$Q$2:$Q$800="Reopened")) * (ISNUMBER(SEARCH('Catalogue Page'!$C$2:$C$800, $E$2))))} -> 3 | G13: {=SUMPRODUCT(('Catalogue Page'!$G$2:$G$800="UAT") * ('Catalogue Page'!$Q$2:$Q$800="Hold") * (ISNUMBER(SEARCH('Catalogue Page'!$C$2:$C$800, $E$2))))} -> 18
C14: Header - Footer | D14: {=SUMPRODUCT(('Header & Footer'!$F$2:$F$800="UAT") * ('Header & Footer'!$A$2:$A$800<>"") * (ISNUMBER(SEARCH('Header & Footer'!$C$2:$C$800, $E$2))))} -> 25 | E14: {=SUMPRODUCT(('Header & Footer'!$F$2:$F$799="UAT") * ('Header & Footer'!$R$2:$R$799="Resolved") * (ISNUMBER(SEARCH('Header & Footer'!$C$2:$C$799, $E$2))))} -> 17 | F14: {=SUMPRODUCT(('Header & Footer'!$F$2:$F$799="UAT") * (('Header & Footer'!$R$2:$R$799="Open") + ('Header & Footer'!$R$2:$R$799="Reopened")) * (ISNUMBER(SEARCH('Header & Footer'!$C$2:$C$799, $E$2))))} -> 1 | G14: {=SUMPRODUCT(('Header & Footer'!$F$2:$F$799="UAT") * ('Header & Footer'!$R$2:$R$799="Hold") * (ISNUMBER(SEARCH('Header & Footer'!$C$2:$C$799, $E$2))))} -> 7
C15: Total | D15: =SUM(D11:D14) -> 397 | E15: =SUM(E11:E14) -> 300 | F15: =SUM(F11:F14) -> 36 | G15: =SUM(G11:G14) -> 61
I16: Fixed on HTML | J16: Pending/Reopen | K16: Tested on (Version Name)
B17: HTML/CSS | C17: Homepage | D17: {=SUMPRODUCT(('Home Page'!$G$2:$G$799="HTML/CSS") * ('Home Page'!$A$2:$A$799<>"") * (ISNUMBER(SEARCH('Home Page'!$C$2:$C$799, $E$2))))} -> 12 | E17: {=SUMPRODUCT(('Home Page'!$G$2:$G$799="HTML/CSS") * ('Home Page'!$Q$2:$Q$799="Resolved") * (ISNUMBER(SEARCH('Home Page'!$C$2:$C$799, $E$2))))} -> 7 | F17: {=SUMPRODUCT(('Home Page'!$G$2:$G$799="HTML/CSS") * (('Home Page'!$Q$2:$Q$799="Open") + ('Home Page'!$Q$2:$Q$799="Reopened")) * (ISNUMBER(SEARCH('Home Page'!$C$2:$C$799, $E$2))))} -> 4 | G17: {=SUMPRODUCT(('Home Page'!$G$2:$G$799="HTML/CSS") * ('Home Page'!$Q$2:$Q$799="Hold") * (ISNUMBER(SEARCH('Home Page'!$C$2:$C$799, $E$2))))} -> 1 | I17: {=SUMPRODUCT(('Home Page'!$G$2:$G$800="HTML/CSS") * (('Home Page'!$Q$2:$Q$800="Open") + ('Home Page'!$Q$2:$Q$800="Reopened")) * ('Home Page'!$T$2:$T$800="Fixed") * (ISNUMBER(SEARCH('Home Page'!$C$2:$C$800, $E$2))))} -> 2 | J17: {=SUMPRODUCT(('Home Page'!$G$2:$G$800="HTML/CSS") * (('Home Page'!$Q$2:$Q$800="Open") + ('Home Page'!$Q$2:$Q$800="Reopened")) * (('Home Page'!$T$2:$T$800="Reopen") + ('Home Page'!$T$2:$T$800="Pending")) * (ISNUMBER(SEARCH('Home Page'!$C$2:$C$800, $E$2))))} -> 0 | K17: v50
C18: Product | D18: {=SUMPRODUCT(('Product Details Page'!$G$2:$G$800="HTML/CSS") * ('Product Details Page'!$A$2:$A$800<>"") * (ISNUMBER(SEARCH('Product Details Page'!$C$2:$C$800, $E$2)))) + SUMPRODUCT(('Credit Card Pages'!$F$2:$F$800="HTML/CSS") * ('Credit Card Pages'!$A$2:$A$800<>"") * (ISNUMBER(SEARCH('Credit Card Pages'!$C$2:$C$800, $E$2))))} -> 54 | E18: {=SUMPRODUCT(('Product Details Page'!$G$2:$G$800="HTML/CSS") * ('Product Details Page'!$Q$2:$Q$800="Resolved") * (ISNUMBER(SEARCH('Product Details Page'!$C$2:$C$800, $E$2)))) + SUMPRODUCT(('Credit Card Pages'!$F$2:$F$800="HTML/CSS") * ('Credit Card Pages'!$R$2:$R$800="Resolved") * (ISNUMBER(SEARCH('Credit Card Pages'!$C$2:$C$800, $E$2))))} -> 38 | F18: {=SUMPRODUCT(('Product Details Page'!$G$2:$G$800="HTML/CSS") * (('Product Details Page'!$Q$2:$Q$800="Open") + ('Product Details Page'!$Q$2:$Q$800="Reopened")) * (ISNUMBER(SEARCH('Product Details Page'!$C$2:$C$800, $E$2)))) + SUMPRODUCT(('Credit Card Pages'!$F$2:$F$800="HTML/CSS") * (('Credit Card Pages'!$R$2:$R$800="Open") + ('Credit Card Pages'!$R$2:$R$800="Reopened")) * (ISNUMBER(SEARCH('Credit Card Pages'!$C$2:$C$800, $E$2))))} -> 16 | G18: {=SUMPRODUCT(('Product Details Page'!$G$2:$G$800="HTML/CSS") * ('Product Details Page'!$Q$2:$Q$800="Hold") * (ISNUMBER(SEARCH('Product Details Page'!$C$2:$C$800, $E$2)))) + SUMPRODUCT(('Credit Card Pages'!$F$2:$F$800="HTML/CSS") * ('Credit Card Pages'!$R$2:$R$800="Hold") * (ISNUMBER(SEARCH('Credit Card Pages'!$C$2:$C$800, $E$2))))} -> 0 | I18: {=SUMPRODUCT(('Product Details Page'!$G$2:$G$800="HTML/CSS") * (('Product Details Page'!$Q$2:$Q$800="Open") + ('Product Details Page'!$Q$2:$Q$800="Reopened")) * ('Product Details Page'!$T$2:$T$800="Fixed") * (ISNUMBER(SEARCH('Product Details Page'!$C$2:$C$800, $E$2)))) + SUMPRODUCT(('Credit Card Pages'!$F$2:$F$800="HTML/CSS") * (('Credit Card Pages'!$R$2:$R$800="Open") + ('Credit Card Pages'!$R$2:$R$800="Reopened")) * ('Credit Card Pages'!$U$2:$U$800="Fixed") * (ISNUMBER(SEARCH('Credit Card Pages'!$C$2:$C$800, $E$2))))} -> 0 | J18: {=SUMPRODUCT(('Product Details Page'!$G$2:$G$800="HTML/CSS") * (('Product Details Page'!$Q$2:$Q$800="Open") + ('Product Details Page'!$Q$2:$Q$800="Reopened")) * (('Product Details Page'!$T$2:$T$800="Reopen") + ('Product Details Page'!$T$2:$T$800="Pending")) * (ISNUMBER(SEARCH('Product Details Page'!$C$2:$C$800, $E$2)))) + SUMPRODUCT(('Credit Card Pages'!$F$2:$F$800="HTML/CSS") * (('Credit Card Pages'!$R$2:$R$800="Open") + ('Credit Card Pages'!$R$2:$R$800="Reopened")) * (('Credit Card Pages'!$U$2:$U$800="Reopen") + ('Credit Card Pages'!$U$2:$U$800="Pending")) * (ISNUMBER(SEARCH('Credit Card Pages'!$C$2:$C$800, $E$2))))} -> 4 | K18: v50 - 1
C19: Catalogue | D19: {=SUMPRODUCT(('Catalogue Page'!$G$2:$G$800="HTML/CSS") * ('Catalogue Page'!$A$2:$A$800<>"") * (ISNUMBER(SEARCH('Catalogue Page'!$C$2:$C$800, $E$2))))} -> 50 | E19: {=SUMPRODUCT(('Catalogue Page'!$G$2:$G$800="HTML/CSS") * ('Catalogue Page'!$Q$2:$Q$800="Resolved") * (ISNUMBER(SEARCH('Catalogue Page'!$C$2:$C$800, $E$2))))} -> 26 | F19: {=SUMPRODUCT(('Catalogue Page'!$G$2:$G$800="HTML/CSS") * (('Catalogue Page'!$Q$2:$Q$800="Open") + ('Catalogue Page'!$Q$2:$Q$800="Reopened")) * (ISNUMBER(SEARCH('Catalogue Page'!$C$2:$C$800, $E$2))))} -> 24 | G19: {=SUMPRODUCT(('Catalogue Page'!$G$2:$G$800="HTML/CSS") * ('Catalogue Page'!$Q$2:$Q$800="Hold") * (ISNUMBER(SEARCH('Catalogue Page'!$C$2:$C$800, $E$2))))} -> 0 | I19: {=SUMPRODUCT(('Catalogue Page'!$G$2:$G$800="HTML/CSS") * (('Catalogue Page'!$Q$2:$Q$800="Open") + ('Catalogue Page'!$Q$2:$Q$800="Reopened")) * ('Catalogue Page'!$T$2:$T$800="Fixed") * (ISNUMBER(SEARCH('Catalogue Page'!$C$2:$C$800, $E$2))))} -> 2 | J19: {=SUMPRODUCT(('Catalogue Page'!$G$2:$G$800="HTML/CSS") * (('Catalogue Page'!$Q$2:$Q$800="Open") + ('Catalogue Page'!$Q$2:$Q$800="Reopened")) * (('Catalogue Page'!$T$2:$T$800="Reopen") + ('Catalogue Page'!$T$2:$T$800="Pending")) * (ISNUMBER(SEARCH('Catalogue Page'!$C$2:$C$800, $E$2))))} -> 12 | K19: sbi_card_catalogue-fixes-for-UAT
C20: Header - Footer | D20: {=SUMPRODUCT(('Header & Footer'!$F$2:$F$800="HTML/CSS") * ('Header & Footer'!$A$2:$A$800<>"") * (ISNUMBER(SEARCH('Header & Footer'!$C$2:$C$800, $E$2))))} -> 25 | E20: {=SUMPRODUCT(('Header & Footer'!$F$2:$F$799="HTML/CSS") * ('Header & Footer'!$R$2:$R$799="Resolved") * (ISNUMBER(SEARCH('Header & Footer'!$C$2:$C$799, $E$2))))} -> 10 | F20: {=SUMPRODUCT(('Header & Footer'!$F$2:$F$799="HTML/CSS") * (('Header & Footer'!$R$2:$R$799="Open") + ('Header & Footer'!$R$2:$R$799="Reopened")) * (ISNUMBER(SEARCH('Header & Footer'!$C$2:$C$799, $E$2))))} -> 15 | G20: {=SUMPRODUCT(('Header & Footer'!$F$2:$F$799="HTML/CSS") * ('Header & Footer'!$R$2:$R$799="Hold") * (ISNUMBER(SEARCH('Header & Footer'!$C$2:$C$799, $E$2))))} -> 0 | I20: {=SUMPRODUCT(('Header & Footer'!$F$2:$F$799="HTML/CSS") * (('Header & Footer'!$R$2:$R$799="Open") + ('Header & Footer'!$R$2:$R$799="Reopened")) * ('Header & Footer'!$U$2:$U$799="Fixed") * (ISNUMBER(SEARCH('Header & Footer'!$C$2:$C$799, $E$2))))} -> 0 | J20: {=SUMPRODUCT(('Header & Footer'!$F$2:$F$799="HTML/CSS") * (('Header & Footer'!$R$2:$R$799="Open") + ('Header & Footer'!$R$2:$R$799="Reopened")) * (('Header & Footer'!$U$2:$U$799="Reopen") + ('Header & Footer'!$U$2:$U$799="Pending")) * (ISNUMBER(SEARCH('Header & Footer'!$C$2:$C$799, $E$2))))} -> 9 | K20: v50 - 2
C21: Total | D21: =SUM(D17:D20) -> 141 | E21: =SUM(E17:E20) -> 81 | F21: =SUM(F17:F20) -> 59 | G21: =SUM(G17:G20) -> 1 | I21: =SUM(I17:I20) -> 4 | J21: =SUM(J17:J20) -> 25
C23: Grand Total | D23: =SUM(D9,D15,D21) -> 729 | E23: =SUM(E9,E15,E21) -> 476 | F23: =SUM(F9,F15,F21) -> 190 | G23: =SUM(G9,G15,G21) -> 63

Sheet URLS
A1: Sr No. | B1: Page | C1: PVT URLs | D1: Category | E1: Theme | F1: E-Apply | G1: Network Privileges | H1: UAT URL | I1: devsit URL Received on | J1: Content Testing | K1: Link Redirections | L1: Similar Card | M1: Product Videos | N1: Creatives Testing | O1: End to End Testing | P1: Remarks
A2: 1 | B2: Home Page | C2: https://sbi-pvt.sbicard.com/html/en/home.html | D2: - | E2: - | F2: - | H2: https://sbi-devsit1.sbicard.com/html/en/home.html | J2: Done | K2: Done | L2: - | M2: -
A3: 2 | B3: Product Details Page | D3: - | E3: - | F3: - | H3: https://sbi-devsit1.sbicard.com/html/en/reliancesbicard.html | I3: 24th Dec 2025 | J3: - | K3: - | L3: - | M3: -
A4: 3 | B4: Catalogue Page | C4: https://sbi-pvt.sbicard.com/en/personal/credit-cards.html | D4: - | E4: - | F4: - | H4: https://sbi-devsit1.sbicard.com/en/personal/credit-cards.html | I4: 14th Jan 2026 | J4: Done | K4: Done | L4: - | M4: - | P4: 06/02/2026 - The old pvt link https://sbi-pvt.sbicard.com/html/en/personal/credit-cards.html has been changed to the new catalogue page - https://sbi-pvt.sbicard.com/html/en/product-catalogue.html#featured 29/01/2026 - New link was shared on UAT Discussion call - https://sbi-devsit1.sbicard.com/html/en/personal/credit-cards.html#featured Need a confirmation whether to switch the old link with the new and start testing on the new one or to keep following the old one.
A5: 4 | B5: Tata Neu Plus SBI Card | C5: https://sbi-pvt.sbicard.com/html/en/personal/credit-cards/tata-neu-plus-sbi-card.html | D5: Lifestyle Card | E5: Light | F5: Yes | H5: https://sbi-devsit1.sbicard.com/html/en/personal/credit-cards/tata-neu-plus-sbi-card.html | I5: 17th Jan 2026 | J5: Done | K5: Done | L5: Done | M5: Done | N5: Done | P5: 06/02/2026 - Creative wise testing done op PVT
A6: 5 | B6: SBI Card Elite | C6: https://sbi-pvt.sbicard.com/html/en/personal/credit-cards/sbi-card-elite.html | D6: Lifestyle Card | E6: Dark + Gold ( Elite theme) | F6: Yes | G6: Yes(Mc/Rupay) | H6: https://sbi-devsit1.sbicard.com/html/en/personal/credit-cards/sbi-card-elite.html | I6: 17th Jan 2026 | L6: Done | N6: Done | P6: 06/02/2026 - Creative wise testing done op PVT
A7: 6 | B7: Cashback SBI Card | C7: https://sbi-pvt.sbicard.com/html/en/personal/credit-cards/cashback-sbi-card.html | D7: Reward Cards | E7: Light theme (Cashback theme) | F7: Yes | H7: https://sbi-devsit1.sbicard.com/html/en/personal/credit-cards/cashback-sbi-card.html | I7: 22nd Jan 2026 | L7: Done | N7: Done | P7: 06/02/2026 - Creative wise testing done on PVT
A8: 7 | B8: SBI Card Pulse | C8: https://sbi-pvt.sbicard.com/html/en/personal/credit-cards/sbi-card-pulse.html | D8: Lifestyle Card | E8: Dark (Pulse theme) | F8: Yes | H8: https://sbi-devsit1.sbicard.com/html/en/personal/credit-cards/sbi-card-pulse.html | I8: 17th Jan 2026 | L8: Done | N8: Done | P8: 06/02/2026 - Creative wise testing done op PVT
A9: 8 | B9: Air India SBI Signature Card | C9: https://sbi-pvt.sbicard.com/html/en/personal/credit-cards/air-india-sbi-signature-card.html | D9: Travel & Fuel Card | E9: Light | F9: No | H9: https://sbi-devsit1.sbicard.com/html/en/personal/credit-cards/air-india-sbi-signature-card.html | I9: 22nd Jan 2026 | L9: Done | N9: Done | P9: 06/02/2026 - Creative wise testing done on PVT
A10: 9 | B10: Air India SBI Platinum Card | C10: https://sbi-pvt.sbicard.com/html/en/personal/credit-cards/air-india-sbi-platinum-card.html | D10: Travel & Fuel Card | E10: Light | F10: No | H10: https://sbi-devsit1.sbicard.com/html/en/personal/credit-cards/air-india-sbi-platinum-card.html | I10: 22nd Jan 2026 | L10: Done | N10: Done | P10: 06/02/2026 - Creative wise testing done on PVT
A11: 10 | B11: Apollo SBI Card Select | C11: https://sbi-pvt.sbicard.com/html/en/personal/credit-cards/apollo-sbi-card-select.html | D11: Reward Cards | E11: Light | F11: Yes | H11: https://sbi-devsit1.sbicard.com/html/en/personal/credit-cards/apollo-sbi-card-select.html | I11: 22nd Jan 2026 | L11: Done | N11: Done | P11: 06/02/2026 - Creative wise testing done on PVT
A12: 11 | B12: Flipkart SBI Card | C12: https://sbi-pvt.sbicard.com/html/en/personal/credit-cards/flipkart-sbi-card.html | D12: Reward Cards | E12: Light | F12: Yes | H12: https://sbi-devsit1.sbicard.com/html/en/personal/credit-cards/flipkart-sbi-card.html | I12: 17th Jan 2026 | L12: Done | N12: Done | P12: 06/02/2026 - Creative wise testing done on PVT
A13: 12 | B13: Landmark Rewards SBI Card Select | C13: https://sbi-pvt.sbicard.com/html/en/personal/credit-cards/landmark-sbi-card-select.html | D13: Shopping Card | E13: Light | F13: Yes | H13: https://sbi-devsit1.sbicard.com/html/en/personal/credit-cards/landmark-sbi-card-select.html | I13: 17th Jan 2026 | L13: Done | N13: Done | P13: 06/02/2026 - Creative wise testing done on PVT 29/01/2026 - Chagned to New link shared on Discussion call - https://sbi-devsit1.sbicard.com/html/en/personal/credit-cards/landmark-sbi-card-select.html Old link was - https://sbi-devsit1.sbicard.com/html/en/personal/credit-cards/landmark-rewards-sbi-card-select.html
A14: 13 | B14: Landmark Rewards SBI Card | C14: https://sbi-pvt.sbicard.com/html/en/personal/credit-cards/landmark-sbi-card.html | D14: Shopping Card | E14: Light | F14: Yes | H14: https://sbi-devsit1.sbicard.com/html/en/personal/credit-cards/landmark-rewards-sbi-card.html | L14: Done | N14: Done | P14: 06/02/2026 - The PVT link is not working - https://www.loom.com/share/c46dfd9ce3264fa09bff27fd3737b6f9
A15: 14 | B15: Landmark SBI Card Prime | C15: https://sbi-pvt.sbicard.com/html/en/personal/credit-cards/landmark-sbi-card-prime.html | D15: Shopping Card | E15: Light | F15: Yes | H15: https://sbi-devsit1.sbicard.com/html/en/personal/credit-cards/landmark-sbi-card-prime.html | L15: Done | N15: Done | P15: 06/02/2026 - Creative wise testing done on PVT
A16: 15 | B16: Etihad Guest SBI Card | C16: https://sbi-pvt.sbicard.com/html/en/personal/credit-cards/etihad-guest-sbi-card.html | D16: Travel & Fuel Card | E16: Light | F16: No | G16: Yes(Mc/Rupay) | H16: https://sbi-devsit1.sbicard.com/html/en/personal/credit-cards/etihad-guest-sbi-card.html | I16: 22nd Jan 2026 | L16: Done | N16: Done | P16: 06/02/2026 - Creative wise testing done on PVT
A17: 16 | B17: Doctors SBI Card | C17: https://sbi-pvt.sbicard.com/html/en/personal/credit-cards/doctors-sbi-card.html | D17: Lifestyle Card | E17: Light | F17: No | H17: https://sbi-devsit1.sbicard.com/html/en/personal/credit-cards/doctors-sbi-card.html | I17: 17th Jan 2026 | L17: Done | N17: Done | P17: 06/02/2026 - Creative wise testing done op PVT
A18: 17 | B18: BPCL SBI Card | C18: https://sbi-pvt.sbicard.com/html/en/personal/credit-cards/bpcl-sbi-card.html | D18: Travel & Fuel Card | E18: Dark | F18: Yes | H18: https://sbi-devsit1.sbicard.com/html/en/personal/credit-cards/bpcl-sbi-card.html | I18: 22nd Jan 2026 | L18: Done | N18: Done | P18: 06/02/2026 - Creative wise testing done on PVT
A19: 18 | B19: Etihad Guest SBI Premier Card | C19: https://sbi-pvt.sbicard.com/html/en/personal/credit-cards/etihad-guest-sbi-premier-card.html | D19: Travel & Fuel Card | E19: Dark | F19: No | G19: Yes(Mc/Rupay) | H19: https://sbi-devsit1.sbicard.com/html/en/personal/credit-cards/etihad-guest-sbi-premier-card.html | I19: 22nd Jan 2026 | L19: Done | N19: Done | P19: 06/02/2026 - Creative wise testing done on PVT
A20: 19 | B20: Doctors with IMA SBI Card | C20: https://sbi-pvt.sbicard.com/html/en/personal/credit-cards/doctors-ima-sbi-card.html | D20: Lifestyle Card | E20: Light | F20: No | H20: https://sbi-devsit1.sbicard.com/html/en/personal/credit-cards/doctors-ima-sbi-card.html | I20: 17th Jan 2026 | L20: Done | N20: Done | P20: 06/02/2026 - The PVT URL is not redirecting to the card page - https://www.loom.com/share/112cdc78107d4d928ebff913384b86b7 29/01/2026 - Chagned to New link shared on Discussion call - https://sbi-devsit1.sbicard.com/html/en/personal/credit-cards/doctors-ima-sbi-card.html Old link was - https://sbi-devsit1.sbicard.com/html/en/personal/credit-cards/doctors-with-ima-sbi-card.html
A21: 20 | B21: BPCL SBI Card Octane | C21: https://sbi-pvt.sbicard.com/html/en/personal/credit-cards/bpcl-sbi-card-octane.html | D21: Travel & Fuel Card | E21: Dark | F21: Yes | H21: https://sbi-devsit1.sbicard.com/html/en/personal/credit-cards/bpcl-sbi-card-octane.html | I21: 22nd Jan 2026 | L21: Done | N21: Done | P21: 06/02/2026 - Creative wise testing done on PVT
A22: 21 | B22: Club Vistara SBI Card | C22: https://sbi-pvt.sbicard.com/html/en/personal/credit-cards/club-vistara-sbi-card.html | D22: Travel & Fuel Card | E22: Light | F22: No | H22: https://sbi-devsit1.sbicard.com/html/en/personal/credit-cards/club-vistara-sbi-card.html | I22: 22nd Jan 2026 | L22: Done | N22: Done | P22: 06/02/2026 - Creative wise testing done on PVT
A23: 22 | B23: Apollo SBI Card | C23: https://sbi-pvt.sbicard.com/html/en/personal/credit-cards/apollo-sbi-card.html | D23: Reward Cards | E23: Light | F23: No | H23: https://sbi-devsit1.sbicard.com/html/en/personal/credit-cards/apollo-sbi-card.html | I23: 22nd Jan 2026 | L23: Done | N23: Done | P23: 06/02/2026 - Creative wise testing done on PVT
A24: 23 | B24: Club Vistara SBI Card Prime | C24: https://sbi-pvt.sbicard.com/html/en/personal/credit-cards/club-vistara-sbi-card-prime.html | D24: Travel & Fuel Card | E24: Light | F24: No | H24: https://sbi-devsit1.sbicard.com/html/en/personal/credit-cards/club-vistara-sbi-card-prime.html | I24: 22nd Jan 2026 | L24: Done | N24: Done | P24: 06/02/2026 - Creative wise testing done on PVT
A25: 24 | B25: IRCTC SBI Platinum Card | C25: https://sbi-pvt.sbicard.com/html/en/personal/credit-cards/irctc-sbi-platinum-card.html | D25: Travel & Fuel Card | E25: Light | F25: Yes | G25: Yes(Mc/Rupay) | H25: https://sbi-devsit1.sbicard.com/html/en/personal/credit-cards/irctc-sbi-platinum-card.html | L25: Done | N25: Done | P25: 06/02/2026 - Creative wise testing done on PVT
A26: 25 | B26: IRCTC Premier Card | C26: https://sbi-pvt.sbicard.com/html/en/personal/credit-cards/irctc-premier-card.html | D26: Travel & Fuel Card | E26: Light | F26: Yes | G26: Yes(Mc/Rupay) | H26: https://sbi-devsit1.sbicard.com/html/en/personal/credit-cards/irctc-premier-card.html | I26: 22nd Jan 2026 | L26: Done | N26: Done | P26: 06/02/2026 - Creative wise testing done on PVT
A27: 26 | B27: OLA Money SBI Card | C27: https://sbi-pvt.sbicard.com/html/en/personal/credit-cards/ola-money-sbi-card.html | D27: Reward Cards | E27: Light | F27: No | H27: https://sbi-devsit1.sbicard.com/html/en/personal/credit-cards/ola-money-sbi-card.html | L27: Done | N27: Done | P27: 06/02/2026 - Creative wise testing done on PVT
A28: 27 | B28: Krisflyer SBI Card | C28: https://sbi-pvt.sbicard.com/html/en/personal/credit-cards/krisflyer-sbi-card.html | D28: Travel & Fuel Card | E28: Light | F28: Yes | H28: https://sbi-devsit1.sbicard.com/html/en/personal/credit-cards/krisflyer-sbi-card.html | L28: Done | N28: Done | P28: 06/02/2026 - Creative wise testing done on PVT
A29: 28 | B29: Krisflyer SBI Card Apex | C29: https://sbi-pvt.sbicard.com/html/en/personal/credit-cards/krisflyer-sbi-card-apex.html | D29: Travel & Fuel Card | E29: Dark + Gold | F29: Yes | H29: https://sbi-devsit1.sbicard.com/html/en/personal/credit-cards/krisflyer-sbi-card-apex.html | L29: Done | N29: Done | P29: 06/02/2026 - Creative wise testing done on PVT
A30: 29 | B30: Tata Neu Infinity SBI Card | C30: https://sbi-pvt.sbicard.com/html/en/personal/credit-cards/tata-neu-infinity-sbi-card.html | D30: Lifestyle Card | E30: Light | F30: Yes | H30: https://sbi-devsit1.sbicard.com/html/en/personal/credit-cards/tata-neu-infinity-sbi-card.html | I30: 17th Jan 2026 | L30: Done | N30: Done | P30: 06/02/2026 - Creative wise testing done op PVT
A31: 30 | B31: PhonePe SBI Card Purple | C31: https://sbi-pvt.sbicard.com/html/en/personal/credit-cards/phonepe-sbi-card-purple.html | D31: Reward Cards | E31: Light | F31: No | H31: https://sbi-devsit1.sbicard.com/html/en/personal/credit-cards/phonepe-sbi-card-purple.html | I31: 17th Jan 2026 | L31: Done | N31: Done | P31: 06/02/2026 - Creative wise testing done on PVT
A32: 31 | B32: Paytm SBI Card Select | C32: https://sbi-pvt.sbicard.com/html/en/personal/credit-cards/paytm-sbi-card-select.html | D32: Reward Cards | E32: Dark + Gold | F32: No | H32: https://sbi-devsit1.sbicard.com/html/en/personal/credit-cards/paytm-sbi-card-select.html | I32: 22nd Jan 2026 | L32: Done | N32: Done | P32: 06/02/2026 - Creative wise testing done on PVT
A33: 32 | B33: SBI Card Miles Elite | C33: https://sbi-pvt.sbicard.com/html/en/personal/credit-cards/sbi-card-miles-elite.html | D33: Travel & Fuel Card | E33: Light (Miles Theme) | F33: Yes | H33: https://sbi-devsit1.sbicard.com/html/en/personal/credit-cards/sbi-card-miles-elite.html | L33: Done | N33: Done | P33: 06/02/2026 - Creative wise testing done on PVT
A34: 33 | B34: Indigo SBI Card Elite | C34: https://sbi-pvt.sbicard.com/html/en/personal/credit-cards/indigo-sbi-card-elite.html | D34: Travel & Fuel Card | E34: Light | F34: Yes | H34: https://sbi-devsit1.sbicard.com/html/en/personal/credit-cards/indigo-sbi-card-elite.html | I34: 22nd Jan 2026 | L34: Done | N34: Done | P34: 06/02/2026 - Creative wise testing done on PVT
A35: 34 | B35: Reliance SBI Card | C35: https://sbi-pvt.sbicard.com/html/en/personal/credit-cards/reliance-sbi-card.html | D35: Shopping Card | E35: Light | F35: Yes | G35: Yes(Mc/Rupay) | H35: https://sbi-devsit1.sbicard.com/html/en/personal/credit-cards/reliance-sbi-card.html | I35: 22nd Jan 2026 | L35: Done | N35: Done | P35: 06/02/2026 - Creative wise testing done on PVT
A36: 35 | B36: Indigo SBI Card | C36: https://sbi-pvt.sbicard.com/html/en/personal/credit-cards/indigo-sbi-card.html | D36: Travel & Fuel Card | E36: Light | F36: Yes | H36: https://sbi-devsit1.sbicard.com/html/en/personal/credit-cards/indigo-sbi-card.html | I36: 22nd Jan 2026 | L36: Done | N36: Done | P36: 06/02/2026 - Creative wise testing done on PVT
A37: 36 | B37: Reliance SBI Card Prime | C37: https://sbi-pvt.sbicard.com/html/en/personal/credit-cards/reliance-sbi-card-prime.html | D37: Shopping Card | E37: Dark | F37: Yes | G37: Yes(Mc/Rupay) | H37: https://sbi-devsit1.sbicard.com/html/en/personal/credit-cards/reliance-sbi-card-prime.html | I37: 22nd Jan 2026 | L37: Done | N37: Done | P37: 06/02/2026 - Creative wise testing done on PVT
A38: 37 | B38: PhonePe SBI Card Select Black | C38: https://sbi-pvt.sbicard.com/html/en/personal/credit-cards/phonepe-sbi-card-select-black.html | D38: Reward Cards | E38: Dark | F38: No | H38: https://sbi-devsit1.sbicard.com/html/en/personal/credit-cards/phonepe-sbi-card-select-black.html | I38: 17th Jan 2026 | L38: Done | N38: Done | P38: 06/02/2026 - Creative wise testing done on PVT
A39: 38 | B39: PayTM SBI Card | C39: https://sbi-pvt.sbicard.com/html/en/personal/credit-cards/paytm-sbi-card.html | D39: Reward Cards | E39: Light | F39: No | H39: https://sbi-devsit1.sbicard.com/html/en/personal/credit-cards/paytm-sbi-card.html | L39: Done | N39: Done | P39: 06/02/2026 - Creative wise testing done on PVT
A40: 39 | B40: SBI Card Prime | C40: https://sbi-pvt.sbicard.com/html/en/personal/credit-cards/sbi-card-prime.html | D40: Reward Cards | E40: Dark (Prime theme) | F40: Yes | G40: Yes(Mc/Rupay) | H40: https://sbi-devsit1.sbicard.com/html/en/personal/credit-cards/sbi-card-prime.html | I40: 17th Jan 2026 | L40: Done | N40: Done | P40: 06/02/2026 - Creative wise testing done on PVT
...

Sheet Old Pages
A1: Sr No. | B1: Received on | C1: Page | D1: URLs | E1: Skip or Test | F1: Testing Status | G1: Last Updated On | H1: QA Remark
A2: 1 | B2: 46145 | D2: https://sbi-devsit1.sbicard.com/en/security.page | E2: To be Tested
A3: 2 | B3: 46145 | D3: https://sbi-devsit1.sbicard.com/en/eapply.page | E3: To be Tested
A4: 3 | B4: 46145 | D4: https://sbi-devsit1.sbicard.com/en/most-important-terms-and-conditions.page | E4: To be Tested
A5: 4 | B5: 46145 | D5: https://sbi-devsit1.sbicard.com/en/personal/benefits/encash.page | E5: To be Tested
A6: 5 | B6: 46145 | D6: https:///sbi-devsit1.sbicard.com/en/tokenisation.page | E6: To be Tested
A7: 6 | B7: 46145 | D7: https:///sbi-devsit1.sbicard.com/en/personal/benefits/add-on-card.page | E7: Skip
A8: 7 | B8: 46145 | D8: https:///sbi-devsit1.sbicard.com/en/contact-us/personal.page | E8: Skip
A9: 8 | B9: 46145 | D9: https:///sbi-devsit1.sbicard.com/en/personal/credit-cards/simplyfier.page | E9: Skip
A10: 9 | B10: 46145 | D10: https://sbi-devsit1.sbicard.com/en/faq/flexipay.page | E10: To be Tested
A11: 10 | B11: 46145 | D11: https://sbi-devsit1.sbicard.com/en/faq/kyc-norms.page | E11: To be Tested
A12: 11 | B12: 46145 | D12: https://sbi-devsit1.sbicard.com/en/faq/add-on-card.page | E12: Skip
A13: 12 | B13: 46145 | D13: https://sbi-devsit1.sbicard.com/en/tataneu-eapply.page | E13: Skip
... A132: 131 | B132: 46145 | D132: https://sbi-devsit1.sbicard.com/en/personal/offers.page | E132: Skip
D133: All individual Offer pages
A134: 132 | B134: 46145 | D134: https://sbi-devsit1.sbicard.com/en/home.page | E134: To be Tested
A135: 133 | B135: 46145 | D135: https://sbi-devsit1.sbicard.com/en/personal/visa-offers.page | E135: Skip
A136: 134 | B136: 46145 | D136: https://sbi-devsit1.sbicard.com/en/privacy-policy.page | E136: Skip
A137: 135 | B137: 46145 | D137: https://sbi-devsit1.sbicard.com/en/do-not-disturb.page | E137: Skip
A138: 136 | B138: 46145 | D138: https://sbi-devsit1.sbicard.com/en/cardholder-agreement.page | E138: Skip
A139: 137 | B139: 46145 | D139: https://sbi-devsit1.sbicard.com/en/faq.page | E139: Skip
A140: 138 | B140: 46145 | D140: https://sbi-devsit1.sbicard.com/en/blog/home.page | E140: Skip
A141: 139 | B141: 46145 | D141: https://sbi-devsit1.sbicard.com/en/personal/pay.page | E141: To be Tested
A142: 140 | B142: 46145 | D142: https://sbi-devsit1.sbicard.com/en/personal/credit-cards/compare-cards.page | E142: Skip
A143: 141 | B143: 46145 | D143: https://sbi-devsit1.sbicard.com/en/personal/credit-cards.page | E143: Skip
A144: 142 | B144: 46145 | D144: https://sbi-devsit1.sbicard.com/en/disclaimer.page | E144: Skip
A145: 143 | B145: 46145 | D145: https://sbi-devsit1.sbicard.com/en/offer-terms-conditions.page | E145: Skip
... A149: 147 | B149: 46145 | D149: https://sbi-devsit1.sbicard.com/en/personal/rewards.page | E149: Skip
D150: Also, all individual Rewards pages
A151: 148 | B151: 46145 | D151: https://sbi-devsit1.sbicard.com/en/personal/benefits/card-upgrade.page | E151: To be Tested
A152: 149 | B152: 46145 | D152: https://sbi-devsit1.sbicard.com/en/personal/benefits/money-simplified/atm-cash.page | E152: Skip
A153: 150 | B153: 46145 | D153: https://sbi-devsit1.sbicard.com/en/personal/benefits/utility-bill-payments/visa-bill.page | E153: Skip
A154: 151 | B154: 46145 | D154: https://sbi-devsit1.sbicard.com/en/personal/benefits/utility-bill-payments/auto-bill-pay.page | E154: Skip
A155: 152 | B155: 46145 | D155: https://sbi-devsit1.sbicard.com/en/personal/benefits/utility-bill-payments/pay-fast.page | E155: Skip
A156: 153 | B156: 46145 | D156: https://sbi-devsit1.sbicard.com/en/personal/benefits/easy-access-channels/simply-sms.page | E156: Skip
A157: 154 | B157: 46145 | D157: https://sbi-devsit1.sbicard.com/en/personal/benefits/easy-access-channels/yono.page | E157: Skip
A158: 155 | B158: 46145 | D158: https://sbi-devsit1.sbicard.com/en/personal/benefits/easy-access-channels/missed-call-service.page | E158: Skip
A159: 156 | B159: 46145 | D159: https://sbi-devsit1.sbicard.com/en/personal/benefits/utility-bill-payments/recurring-e-mandates.page | E159: To be Tested
A160: 157 | B160: 46145 | D160: https://sbi-devsit1.sbicard.com/en/personal/benefits/utility-bill-payments/register-and-pay.page | E160: To be Tested
A161: 158 | B161: 46145 | D161: https://sbi-devsit1.sbicard.com/en/personal/benefits/easy-access-channels/chatbot.page | E161: Skip
...

Sheet ExclusivePrivileges TextOverlap
A1: Page | B1: Card Face | C1: Privileges | D1: Font Size | E1: SBI Team Remark | F1: Status | G1: Last Tested on | H1: QA Remark
A2: Tata Neu Plus SBI Card | B2: Front | C2: Reward Benefit | D2: Large | F2: Resolved | G2: 46056
A3: Air India SBI Signature Card | B3: Front | C3: Milestone Benefits | D3: Default | F3: Resolved | G3: 46056
A4: Air India SBI Signature Card | B4: Back | C4: Milestone Benefits | D4: Large | F4: Resolved | G4: 46056
A5: Air India SBI Signature Card | B5: Front | C5: Reward Benefits, Milestone Benefits | D5: Large | E5: In reward benefit, we change the order of the points second point we will shift it to 3rd and 3rd to second | F5: Unresolved | G5: 22/02/2026 | H5: 22/02/2026 - We cannot change the order of the bullet points
A6: Air India SBI Platinum Card | B6: Front | C6: Reward Benefits, Milestone Benefits | D6: Large | E6: fuelcharge and welcome benefit also create problem I fixed it | F6: Resolved | G6: 46056
A7: Air India SBI Platinum Card | B7: Back | C7: Reward Benefits | D7: Large | F7: Unresolved | G7: 22/02/2026
A8: Landmark Rewards SBI Card | B8: Front | C8: Reward Benefits | D8: Large | F8: Unresolved | G8: 22/02/2026
A9: Landmark Rewards SBI Card Prime | B9: Front | C9: Reward Benefits | D9: Large | F9: Resolved | G9: 46056
A10: Etihad Guest SBI Card | B10: Front | C10: Reward Benefits | D10: Large | F10: Resolved | G10: 46056
A11: Doctor's SBI Card | B11: Front | C11: Reward Points | D11: Default | F11: Resolved | G11: 46056
A12: Doctor's SBI Card | B12: Front | C12: Reward Points | D12: Large | F12: Unresolved | G12: 22/02/2026
A13: BPCL SBI Card | B13: Front | C13: Reward Benefits | D13: Default | F13: Resolved | G13: 46056
A14: BPCL SBI Card | B14: Front | C14: Reward Benefits | D14: Large | F14: Resolved | G14: 46056
A15: BPCL SBI Card OCTANE | B15: Front | C15: Reward Benefits, Fuel Surcharge Waiver | D15: Large | E15: welcome benefit also create issue , I fixed it | F15: Resolved | G15: 46056
A16: Club Vistara SBI Card | B16: Back | C16: Reward Benefits | D16: Large | F16: Unresolved | G16: 22/02/2026
A17: Club Vistara SBI Card | B17: Front | C17: Milestone Benefits | D17: Large | E17: Shuffle the points 3-1st, 2nd- 2ndrd, 1st -3rd | F17: Unresolved | G17: 22/02/2026 | H17: 22/02/2026 - We cannot change the order of the bullet points
A18: Club Vistara SBI Card | B18: Front | C18: Domestic Lounge Benefits | D18: Default | F18: Resolved | G18: 46056
A19: Club Vistara SBI Card | B19: Back | C19: Domestic Lounge Benefits | D19: Large | F19: Resolved | G19: 46056
A20: Club Vistara SBI Card | B20: Front | C20: Domestic Lounge Benefits | D20: Large | F20: Resolved | G20: 46056
A21: Club Vistara SBI Card | B21: Front | C21: Complimentary Priority Pass Membership | D21: Default | F21: Resolved | G21: 46056
A22: Club Vistara SBI Card | B22: Front | C22: Complimentary Priority Pass Membership | D22: Large | E22: content need to be customized | F22: Unresolved | G22: 46359 | H22: 12/03/2026 - As discussed with Namita ma'am, thecontent of the bullet point at the back of this card should be updated to - "Standard membership of Priority Pass Program is complimentary for 24 months. Usage fee of $27 + applicable taxes will be charged on your Credit Card for visit to the Priority Pass Membership Lounge"
A23: Apollo SBI Card | B23: Back | C23: Welcome Benefits | D23: Default | F23: Resolved | G23: 46056
A24: Club Vistara SBI Card Prime | B24: Front | C24: Milestone Benefits | D24: Default | E24: content need to be customized | F24: Resolved | G24: 13/03/2026 | H24: 13/03/2026 - The issue is resolved on sbi-pvt - https://loom.com/i/a30776291da44dc4b3dc870eb1735cd3
A25: Club Vistara SBI Card Prime | B25: Front | C25: Milestone Benefits | D25: Large | F25: Unresolved | G25: 22/02/2026
A26: Club Vistara SBI Card Prime | B26: Front | C26: Complimentary Priority Pass Membership | D26: Large | E26: Comprehensive car cover was also has some issue , fixed it | F26: Resolved | G26: 46056
A27: IRCTC SBI Platinum Card | B27: Front | C27: Welcome Benefits | D27: Default | F27: Resolved | G27: 46056
A28: IRCTC SBI Platinum Card | B28: Front | C28: Welcome Benefits | D28: Large | F28: Resolved | G28: 46056
A29: IRCTC SBI Platinum Card | B29: Back | C29: Travel Offers from IRCTC | D29: Small | F29: Resolved | G29: 46056
A30: IRCTC SBI Platinum Card | B30: Back | C30: Travel Offers from IRCTC | D30: Default | E30: Content is not same aslo change every tiles not just two | F30: Resolved | G30: 46056
A31: IRCTC SBI Platinum Card | B31: Back | C31: Travel Offers from IRCTC | D31: Large | F31: Unresolved | G31: 22/02/2026
A32: IRCTC SBI Premier | B32: Front | C32: Value Back Benefits | D32: Large | F32: Resolved | G32: 46056
A33: IRCTC SBI Premier | B33: Front | C33: Reward Benefits | D33: Default | F33: Resolved | G33: 46056
A34: IRCTC SBI Premier | B34: Front | C34: Reward Benefits | D34: Large | E34: fuel surcharge waiver was also creating issue, I fixed it | F34: Unresolved | G34: 22/02/2026
A35: KrisFlyer SBI Card APEX | B35: Front | C35: Milestone Benefits | D35: Large | E35: welcome, lounge and fuewlcharge also corrected Also, made 1st point to 3rd in milestone | F35: Unresolved | G35: 22/02/2026
A36: TATA NEU INFINITY SBI CARD | B36: Front | C36: Reward Benefits | D36: Large | F36: Resolved | G36: 46056
A37: PhonePe SBI Card PURPLE | B37: Front | C37: PhonePe Rewards | D37: Large | F37: Resolved | G37: 46056
A38: SBI Card Miles Elite | B38: No Accessibility Bar | C38: No Accessibility Bar | D38: No Accessibility Bar | F38: Resolved | G38: 46056
A39: INDIGO SBI CARD ELITE | B39: Front | C39: Welcome Benefits | D39: Large | E39: welcome, renewal, domestic and insurance also corrected | F39: Resolved | G39: 46056
A40: Reliance SBI Card | B40: Front | C40: Reward Benefits | D40: Large | F40: Resolved | G40: 46056
...

Sheet Product Videos Test Cases
A1: Card Names | B1: Video Titles | C1: Expected Product Video URLs | D1: Actual Product Video URLs | E1: Video URLs | F1: Video Titles | G1: Video Thumbnails | H1: QA Remark
A2: SBI Card ELITE | B2: 1.) SBI Card Elite Features & Benefits 2.) Unwind in Luxury | SBI Card ELITE 3.) Live a rewarding life with SBI Card ELITE 4.) Comfort and Class in Travel Always | SBI Card ELITE 5.) Elevate your flying experience | SBI Card ELITE 6.) SBI Card Elite | Credit Card Benefits & Rewards | Premium Reward Card | C2: 1.) https://www.youtube.com/watch?v=SxuFU7C5Lxo 2.) https://www.youtube.com/watch?v=7gBHGP99YpU 3.) https://www.youtube.com/watch?v=e5mDpMcXMQs 4.) https://www.youtube.com/watch?v=KKDq1jPKqWM 5.) https://www.youtube.com/watch?v=QGXYDpw45mc 6.) https://www.youtube.com/watch?v=o30QyC6tuiY | D2: 1.) https://www.youtube.com/watch?v=SxuFU7C5Lxo 2.) https://www.youtube.com/watch?v=7gBHGP99YpU 3) https://www.youtube.com/watch?v=e5mDpMcXMQs 4.) https://www.youtube.com/watch?v=KKDq1jPKqWM 5.) https://www.youtube.com/watch?v=QGXYDpw45mc 6.) https://www.youtube.com/watch?v=o30QyC6tuiY | E2: Pass | F2: Pass | G2: Fail | H2: 13/03/2026 - The 4th video thumbnail is breaking the alignemnt - 10/03/2026 - 4th Video still has dummy thumbnail because it was not provided in the thumbnail file shared.
A3: SBI Card PULSE | B3: 1.) Move towards a Fitter You | SBI Card PULSE | C3: 1.) https://www.youtube.com/watch?v=VlUwJtMObJM | D3: 1.) https://www.youtube.com/watch?v=VlUwJtMObJM | E3: Pass | F3: Pass | G3: Pass
A4: Tata Neu Infinity SBI Card | B4: 1.) Welcome Benefit - TATA Neu Infinity SBI Credit Card 2.) Introducing the Tata Neu Infinity SBI Credit Card 3.) Introducing the Tata Neu Infinity SBI Credit Card | C4: 1.) https://www.youtube.com/shorts/9W-yd2nKbIY 2.) https://www.youtube.com/shorts/NFFdaffkdy8 3.) https://www.youtube.com/shorts/NFFdaffkdy8 | D4: 1.) https://www.youtube.com/shorts/9W-yd2nKbIY 2.) https://www.youtube.com/shorts/NFFdaffkdy8 3.) https://www.youtube.com/shorts/NFFdaffkdy8 | E4: Pass | F4: Pass | G4: Pass | H4: 17/03/2026 - The issue is now resolved - https://loom.com/i/aa7316864f084b18ab60190a9d619e2f 16/03/2026 - Thumbnails not yet added.
A5: Tata Neu Plus SBI Card | B5: No Videos Provided | C5: No URLs Provided | D5: - | E5: - | F5: - | G5: -
A6: Doctor's SBI Card (in association with IMA) | B6: 1.) Doctor's SBI Card | Credit Card Benefits & Rewards | SBI Doctors Credit Card 2.) Doctor's SBI Card | Credit Card Benefits & Rewards | SBI Card | C6: 1.) https://www.youtube.com/watch?v=8x2fWFLDk2k 2.) https://www.youtube.com/watch?v=FoZaQr9zHSY | D6: 1.) https://www.youtube.com/watch?v=8x2fWFLDk2k 2.) https://www.youtube.com/watch?v=FoZaQr9zHSY | E6: Pass | F6: Pass | G6: Pass
A7: Doctor's SBI Card | B7: 1.) Doctor's SBI Card | Credit Card Benefits & Rewards | SBI Card 2.) Doctor's SBI Card | Credit Card Benefits & Rewards | SBI Doctors Credit Card | C7: 1.) https://www.youtube.com/watch?v=FoZaQr9zHSY 2.) https://www.youtube.com/watch?v=8x2fWFLDk2k | D7: 1.) https://www.youtube.com/watch?v=FoZaQr9zHSY 2.) https://www.youtube.com/watch?v=8x2fWFLDk2k | E7: Pass | F7: Pass | G7: Pass | H7: 16/03/2026 - The 2nd video now has the thumbnail - https://loom.com/i/311c6cc84ff140c3a7e700314110826b 11/03/2026 - The 2nd Video still has dummy thumbnail - https://www.loom.com/i/eb436efa965e4c6888a21ca8dae571bf
A8: Aurum Card | B8: No Videos Provided | C8: No URLs Provided | D8: - | E8: - | F8: - | G8: -
A9: Flipkart SBI Card | B9: 1.) Flipkart SBI Card is here! 2.) Flipkart SBI Card is here! 3.) Earn 5% Cashback* on your bookings at Cleartrip with Flipkart SBI Credit Card 4.) Shop your favourite styles on Myntra | C9: 1.) https://www.youtube.com/watch?v=0oO5Uyk7B_I 2.) https://www.youtube.com/shorts/j5_DXAYfPic 3.) https://www.youtube.com/shorts/54MnmbjGibA 4.) https://www.youtube.com/shorts/5rK7lnm0qSw | D9: 1.) https://www.youtube.com/watch?v=0oO5Uyk7B_I 2.) https://www.youtube.com/shorts/j5_DXAYfPic 3.) https://www.youtube.com/shorts/54MnmbjGibA 4.) https://www.youtube.com/shorts/5rK7lnm0qSw | E9: Pass | F9: Pass | G9: Pass | H9: 16/03/2026 - The issue is resolved - https://loom.com/i/049a955950844128a2639c2602034b31 10/03/2026 - 3rd Video Title, the asterisk (*) is missing after the word "Cashback" it should be " Earn 5% Cashback* on your bookings" - https://www.loom.com/i/9bf4efb5917c48c9b979be59b143c672
A10: CASHBACK SBI Card | B10: 1.) #CashbackHarBaar with CASHBACK SBI Card | C10: 1.) https://www.youtube.com/watch?v=84yhgRGvJ2c | D10: 1.) https://www.youtube.com/watch?v=84yhgRGvJ2c | E10: Pass | F10: Pass | G10: Pass | H10: 10/03/2026 - The # was exclude because it was not looking appropriate.
A11: SBI Card PRIME | B11: 1.) Live the PRIME Life | SBI Card PRIME 2.) Celebrate milestones with SBI Card PRIME 3.) Make every birthday special | SBI Card PRIME 4.) Live the PRIME Life | SBI Card PRIME 5.) SBI Card PRIME | Credit Card Benefits & Rewards | SBI Reward Card | C11: 1.) https://www.youtube.com/watch?v=5EYmJfjFlUk 2.) https://www.youtube.com/watch?v=jw_Xvdki6vg 3.) https://www.youtube.com/watch?v=9gmlocZ5sF4 4.) https://www.youtube.com/watch?v=u5y_ktXNh_0 5.) https://www.youtube.com/watch?v=FKiazBp1GhQ | D11: 1.) https://www.youtube.com/watch?v=5EYmJfjFlUk 2.) https://www.youtube.com/watch?v=jw_Xvdki6vg 3.) https://www.youtube.com/watch?v=9gmlocZ5sF4 4.) https://www.youtube.com/watch?v=u5y_ktXNh_0 5.) https://www.youtube.com/watch?v=FKiazBp1GhQ | E11: Pass | F11: Pass | G11: Pass
A12: PhonePe SBI Card SELECT BLACK | B12: 1.) Introducing the PhonePe SBI Card 2.) Enjoy up to 10% Value Back as Reward Points on PhonePe spends 3.) Introducing the PhonePe SBI Card SELECT BLACK | C12: 1.) https://www.youtube.com/watch?v=LxXQmOqU5o4 2.) https://www.youtube.com/shorts/TqMJs7LPtyQ 3.) https://www.youtube.com/shorts/766bJ87bxU4 | D12: 1.) https://www.youtube.com/watch?v=LxXQmOqU5o4 2.) https://www.youtube.com/shorts/TqMJs7LPtyQ 3.) https://www.youtube.com/shorts/766bJ87bxU4 | E12: Pass | F12: Pass | G12: Pass | H12: 16/03/2026 - Issue resolved on sbi-pvt - https://loom.com/i/1a329d9ca4d1421093e35d0d157776c6 11/03/2026 - 2nd Video Title --> It should be "Enjoy up to 10%" instead of "Enjoy upto 10%".
A13: PhonePe SBI Card PURPLE | B13: 1.) Introducing the PhonePe SBI Card | C13: 1.) https:/www.youtube.com/watch?v=LxXQmOqU5o4 | D13: 1.) https://www.youtube.com/watch?v=LxXQmOqU5o4 | E13: Pass | F13: Pass | G13: Pass | H13: 16/03/2026 - Thumbnail uploaded - https://loom.com/i/cc4aba6ab66743e1b83a330df755ee40
A14: OLA Money SBI Card | B14: No Videos Provided | C14: No URLs Provided | D14: - | E14: - | F14: - | G14: -
A15: Apollo SBI Card SELECT | B15: 1.) Apollo SBI Card SELECT - up to 25% Value Back 2.) Apollo SBI Card SELECT - Welcome Benefit 3.) Apollo SBI Card SELECT is here! | C15: 1.)https://www.youtube.com/shorts/_qFyxMC_NJ4 2.)https://www.youtube.com/shorts/SC4fDNM7c7U 3.) https://www.youtube.com/shorts/R3NKC2IA7Bw | D15: 1.) https://www.youtube.com/shorts/_qFyxMC_NJ4 2.) https://www.youtube.com/shorts/SC4fDNM7c7U 3.) https://www.youtube.com/shorts/R3NKC2IA7Bw | E15: Pass | F15: Pass | G15: Pass | H15: 16/03/2026 - Thumbnail uploaded - https://loom.com/i/956063a325644803a924653c2cb2d91d
A16: Apollo SBI Card | B16: 1.) Apollo SBI Credit Card - Discover a world of health, Official Launch Event of Apollo SBI Card | C16: 1.) https:/www.youtube.com/watch?v=SmLKhe04oiA | D16: 1.) https://www.youtube.com/watch?v=SmLKhe04oiA | E16: Pass | F16: Pass | G16: Pass | H16: 16/03/2026 - Thumbnial uploaded - https://loom.com/i/2d629360633d403a91de0800804d2780
A17: Paytm SBI Card SELECT | B17: 1.) Make your Paytm spends rewarding with the Paytm SBI Card Select 2.) Make your Paytm spends rewarding with the Paytm SBI Card SELECT | C17: 1.) https://www.youtube.com/watch?v=a_4Bgh0WlZs 2.) https://www.youtube.com/watch?v=p6lzw95Sm1k | D17: 1.) https://www.youtube.com/watch?v=a_4Bgh0WlZs 2.) https://www.youtube.com/watch?v=p6lzw95Sm1k | E17: Pass | F17: Fail | G17: Fail | H17: 16/03/2026 - The 1st video thumbnail is breaking the alignment - https://www.loom.com/i/b6832df5e60b4a6285960d12f4748f7a Also, the capitalizations in the card name should be "Paytm SBI Card SELECT" in both the video titles.
A18: Paytm SBI Card | B18: 1.) Make your Paytm spends rewarding with the Paytm SBI Card | C18: 1.) https:/www.youtube.com/watch?v=cSntakowRMQ | D18: 1.) https://www.youtube.com/watch?v=cSntakowRMQ | E18: Pass | F18: Pass | G18: Pass | H18: 16/03/2026 - Thumbnail uploaded - https://loom.com/i/06ce81c1075848adb00f500bf1e338ae
A19: Tata Card SELECT | B19: No Videos Provided | C19: No URLs Provided | D19: - | E19: - | F19: - | G19: -
A20: Tata Card | B20: No Videos Provided | C20: No URLs Provided | D20: - | E20: - | F20: - | G20: -
A21: SimplyCLICK SBI Card | B21: 1.) Simply CLICK for online shopping | SBI Card 2.) 10X Reward Points With SimplyCLICK SBI Card 3.) The Many Rewards of the SimplyCLICK SBI Card 4.) SimplyCLICK SBI Card: Your perfect online shopping partner 5.) SimplyClick SBI Card - A Credit Card for the Generation that Shops Online 6.) SBI SimplyCLICK Credit Card | Benefits & Rewards | Shopping Card | C21: 1.) https://www.youtube.com/watch?v=tvBOlhfBK-4 2.) https://www.youtube.com/watch?v=bGOgP94NMvk 3.) https://www.youtube.com/watch?v=wesp58Mc9YA 4.) https://www.youtube.com/watch?v=BAPzyCp1J4M 5.) https://www.youtube.com/watch?v=496VxdV3mDM 6.) https://www.youtube.com/watch?v=J9XLdHfKagE | D21: 1.) https://www.youtube.com/watch?v=tvBOlhfBK-4 2.) https://www.youtube.com/watch?v=bGOgP94NMvk 3.) https://www.youtube.com/watch?v=wesp58Mc9YA 4.) https://www.youtube.com/watch?v=BAPzyCp1J4M 5.) https://www.youtube.com/watch?v=496VxdV3mDM 6.) https://www.youtube.com/watch?v=J9XLdHfKagE | E21: Pass | F21: Pass | G21: Fail | H21: 16/03/2026 - 4 videos still have dummy thumbnails - https://www.loom.com/i/172711acfe964033a1fd2b83c34ffa29
A22: SimplySAVE SBI Card | B22: 1.) SimplySAVE SBI Credit Card | Shopping Credit Card Benefits & Rewards 2.) SimplySAVE SBI Card is simply better! 3.) More savings, more Rewards | SimplySAVE SBI Card 4.) Make your spends rewarding with SimplySAVE SBI Card 5.) SimplySAVE SBI Credit Card | Shopping Credit Card Benefits & Rewards 6.) SimplySAVE SBI Card | Shopping Credit Card Benefits & Rewards | C22: 1.) https://www.youtube.com/watch?v=XTwASXOCJWY 2.) https://www.youtube.com/watch?v=MU3gDxkS-K4 3.) https://www.youtube.com/watch?v=VViQI-Pmu1s 4.) https://www.youtube.com/watch?v=hT_VF9fYMiU 5.) https://www.youtube.com/watch?v=vozHBbdKVAQ 6.) https://www.youtube.com/watch?v=QEJHAk_iyuc | D22: 1.) https://www.youtube.com/watch?v=XTwASXOCJWY 2.) https://www.youtube.com/watch?v=MU3gDxkS-K4 3.) https://www.youtube.com/watch?v=VViQI-Pmu1s 4.) https://www.youtube.com/watch?v=hT_VF9fYMiU 5.) https://www.youtube.com/watch?v=vozHBbdKVAQ 6.) https://www.youtube.com/watch?v=QEJHAk_iyuc | E22: Pass | F22: Pass | G22: Pass | H22: 16/03/2026 - Thumbnails uploaded - https://loom.com/i/df8240d597a44fefad30335a83e89434
A23: Landmark Rewards SBI Card PRIME | B23: 1.) Landmark Rewards SBI Card PRIME | C23: 1.) https:/www.youtube.com/shorts/2Mo71jNeo9s | D23: 1.) https://www.youtube.com/shorts/2Mo71jNeo9s | E23: Pass | F23: Pass | G23: Pass | H23: 16/03/2026 - Thumbnail uploaded - https://loom.com/i/6ee05e35662c483dba21da8fb3a91b50
A24: Landmark Rewards SBI Card SELECT | B24: No Videos Provided | C24: No URLs Provided | D24: - | E24: - | F24: - | G24: -
A25: Landmark Rewards SBI Card | B25: No Videos Provided | C25: No URLs Provided | D25: - | E25: - | F25: - | G25: -
A26: Titan SBI Card | B26: 1.) Introducing the TITAN SBI Card 2.) Get ready to receive a warm welcome and even more rewards! 3.) Get up to 7.5% Cashback* by shopping at Titan stores with Titan SBI Card. | C26: 1.) https://www.youtube.com/shorts/lyOux3jo84U 2.) https://www.youtube.com/shorts/0CnmQQZyVsU 3.) https://www.youtube.com/shorts/pmpogAWTGjQ | D26: 1.) https://www.youtube.com/shorts/lyOux3jo84U 2.) https://www.youtube.com/shorts/0CnmQQZyVsU 3.) https://www.youtube.com/shorts/pmpogAWTGjQ | E26: Pass | F26: Pass | G26: Pass | H26: 17/03/2026 - The issue is now resolved - https://loom.com/i/73afe3d9056e45d78cc7d9f42f724b09 16/03/2026 - 2nd Video is still having a dummy thumbnail - https://www.loom.com/i/c5c4cf8e7d5f40089f477cfd9362a7ec
A27: Reliance SBI Card | B27: No Videos Provided | C27: No URLs Provided | D27: - | E27: - | F27: - | G27: -
A28: Reliance SBI Card PRIME | B28: No Videos Provided | C28: No URLs Provided | D28: - | E28: - | F28: - | G28: -
A29: SBI Card Unnati | B29: No Videos Provided | C29: No URLs Provided | D29: - | E29: - | F29: - | G29: -
A30: Shaurya SBI Card | B30: No Videos Provided | C30: No URLs Provided | D30: - | E30: - | F30: - | G30: -
A31: Shaurya Select SBI Card | B31: No Videos Provided | C31: No URLs Provided | D31: - | E31: - | F31: - | G31: -
A32: IndiGo SBI Card | B32: 1.) Unlock Every Benefit with the IndiGo SBI Card ELITE | C32: 1.) https:/www.youtube.com/shorts/EYSkhcM1HQ4 | D32: 1.) https://www.youtube.com/shorts/EYSkhcM1HQ4 | E32: Pass | F32: Pass | G32: Pass | H32: 16/03/2026 - Thumbnail uploaded - https://loom.com/i/a86b8e71720a415298fd217660dbe2c6
A33: IndiGo SBI Card ELITE | B33: 1.) Start every journey on an ELITE note with IndiGo SBI Card ELITE 2.) Unlock Every Benefit with the IndiGo SBI Card ELITE | C33: 1.) https://www.youtube.com/shorts/D5mtu2yXbUM 2.) https://www.youtube.com/shorts/EYSkhcM1HQ4 | D33: 1.) https://www.youtube.com/shorts/D5mtu2yXbUM 2.) https://www.youtube.com/shorts/EYSkhcM1HQ4 | E33: Pass | F33: Pass | G33: Pass | H33: 16/03/2026 - Thumbnail uploaded - https://loom.com/i/6be27063ca794c8fa8fe704e3c485f8c
A34: KrisFlyer SBI Card | B34: No Videos Provided | C34: No URLs Provided | D34: - | E34: - | F34: - | G34: -
A35: KrisFlyer SBI Card Apex | B35: 1.) KrisFlyer SBI Card APEX - 8 domestic & 8 international complimentary lounge visits per year 2.) KrisFlyer SBI Card Apex - 10,000 KrisFlyer miles on an annual spend of ₹5 Lakhs 3.) Krisflyer SBI Card APEX - 10 Miles on Rs.200 4.) Krisflyer SBI Card APEX - Welcome Benefit 5.) KrisFlyer SBI Card APEX is now live! | C35: 1.) https://www.youtube.com/shorts/EM3xH2WZhP4 2.) https://www.youtube.com/shorts/H7rTWOLLpCw 3.) https://www.youtube.com/shorts/9RaZBCtviOE 4.) https://www.youtube.com/shorts/djWK01XEz4s 5.) https://www.youtube.com/shorts/DKvUixvzV-I | D35: 1.) https://www.youtube.com/shorts/EM3xH2WZhP4 2.) https://www.youtube.com/shorts/H7rTWOLLpCw 3.) https://www.youtube.com/shorts/9RaZBCtviOE 4.) https://www.youtube.com/shorts/djWK01XEz4s 5.) https://www.youtube.com/shorts/DKvUixvzV-I | E35: Pass | F35: Pass | G35: Fail | H35: 16/03/2026 - 3rd Video thumbnail still pending (from HTML Team) - https://loom.com/i/4f5aa20f9a914880835ad45ea74482eb
A36: SBI Card MILES PRIME | B36: No Videos Provided | C36: No URLs Provided | D36: - | E36: - | F36: - | G36: -
A37: SBI Card Miles Elite | B37: No Videos Provided | C37: No URLs Provided | D37: - | E37: - | F37: - | G37: -
A38: SBI Card MILES | B38: 1.) SBI Card Miles is here 2.) SBI Card Miles 3.) SBI Card Miles | C38: 1.) https://www.youtube.com/shorts/dqC5RDPPS2Y 2.) https://www.youtube.com/shorts/E8cowsJswJQ 3.) https://www.youtube.com/shorts/HOz2q_T9Grg | D38: 1.) https://www.youtube.com/shorts/dqC5RDPPS2Y 2.) https://www.youtube.com/shorts/E8cowsJswJQ 3.) https://www.youtube.com/shorts/HOz2q_T9Grg | E38: Pass | F38: Pass | G38: Pass | H38: 16/03/2026 - The Title & Thumbnail issues are resolved - https://loom.com/i/ce40c741ac3b4569a0efb26935f955bb 11/03/2026 - The Video Titles for all are "SBI Miles" instead of - 1.) SBI Card Miles is here 2.) SBI Card Miles 3.) SBI Card Miles
A39: BPCL SBI Card OCTANE | B39: 1.) BPCL SBI Card Octane | Credit Card Benefits & Rewards | SBI Fuel Credit Card | C39: 1.) https:/www.youtube.com/watch?v=_pdIp-w70SE | D39: 1.) https://www.youtube.com/watch?v=_pdIp-w70SE | E39: Pass | F39: Pass | G39: Pass | H39: 16/03/2026 - Thumbnail uploaded - https://loom.com/i/8f9d77d0bcb240ccaf04afffefc094f7
A40: IRCTC SBI Card Premier | B40: 1.) IRCTC SBI Card Premier | Credit Card Features, Benefits and Rewards | C40: 1.) https:/www.youtube.com/watch?v=jKtSjf34duQ | D40: 1.) https://www.youtube.com/watch?v=jKtSjf34duQ | E40: Pass | F40: Pass | G40: Pass | H40: 16/03/2026 - Thumbnail uploaded - https://loom.com/i/db2f43400c4444388176b4216e4ff884
...

Sheet Exclusive Privileges Icons
A6: Card Name | B6: Exclusive Privileges | C6: Privilege Heading | D6: Correct Icon | E6: Correct Format - SVG | F6: Last Tested On | G6: QA Remark
A7: Tata Neu Plus SBI Card | B7: Welcome Gift Reward Benefits Domestic Lounge Benefits Fuel Surcharge Waiver Spend Based Reversal | C7: Pass | D7: Pass | E7: Fail | F7: 46329
A8: SBI Card Elite | B8: Welcome Gift Complimentary Movie Tickets Milestone Privileges ELITE Rewards International Lounge Program Domestic Lounge Program Lowest Forex Markup ITC Silver Tier Membership Exclusive Concierge Service | C8: Pass | D8: Pass | E8: Pass | F8: 13/3/2026 | G8: 13/03/2026 - The ITC Silver Tier Membership svg has been updated on sbi-pvt
A9: Cashback SBI Card | B9: Card Cashback Hassle free Spend Based Reversal Fuel Surcharge Waiver | C9: Pass | D9: Pass | E9: Fail | F9: 46329
A10: SBI Card Pulse | B10: Welcome Gift Health Benefits Exclusive Rewards Milestone Benefits Comprehensive Insurance Cover Lounge Benefits | C10: Pass | D10: Pass | E10: Pass | F10: 46329
A11: Air India SBI Signature Card | B11: Welcome Benefit Reward Benefits Milestone Benefits Lounge Benefit Fuel Surcharge Waiver | C11: Pass | D11: Pass | E11: Pass | F11: 46329
A12: Air India SBI Platinum Card | B12: Welcome Benefit Reward Benefits Milestone Benefits Lounge Benefit Fuel Surcharge Waiver | C12: Pass | D12: Pass | E12: Pass | F12: 46329
A13: Apollo SBI Card Select | B13: Welcome Benefits Health Benefits Reward Points Milestone Benefits Lounge Benefits Fuel Surcharge Waiver | C13: Pass | D13: Pass | E13: Pass | F13: 46329
A14: Flipkart SBI Card | B14: Welcome Benefit Card Cashback Spend Based Reversal Fuel Surcharge Waiver | C14: Pass | D14: Pass | E14: Pass | F14: 46329
A15: Landmark Rewards SBI Card Select | B15: Welcome Benefits Milestone Benefits Reward Benefits Fuel Surcharge Waiver | C15: Pass | D15: Pass | E15: Pass | F15: 46329
A16: Landmark Rewards SBI Card | B16: Welcome Benefits Milestone Benefits Reward Benefits Fuel Surcharge Waiver | C16: Pass | D16: Pass | E16: Pass | F16: 46329
A17: Landmark SBI Card Prime | B17: Welcome Benefits Milestone Benefits Reward Benefits Domestic Lounge Program Complimentary Lounge Program Complimentary Priority Pass Membership Fuel Surcharge Waiver | C17: Pass | D17: Pass | E17: Pass | F17: 46329
A18: Etihad Guest SBI Card | B18: Welcome Benefits Renewal Benefits Milestone Benfits Spend-Based Fee Reversal Insurance Lounge Benefit Fuel Surcharge Waiver | C18: Fail | D18: Fail | E18: Fail | F18: 13/03/2026 | G18: 13/03/2026 - The renewal benefits icons is now other benefits icon - https://loom.com/i/5fa12e73844e460c9f29f23b2580fc57
A19: Doctors SBI Card | B19: Professional Indemnity Insurance Welcome Gift Reward Points Milestone Benefits International Lounge Program Domestic Lounge Program Fuel Surcharge Waiver | C19: Pass | D19: Pass | E19: Pass | F19: 13/3/2026 | G19: 13/03/2026 - Professional Indemnity Insurance icon format is now svg
A20: BPCL SBI Card | B20: Welcome Benefits Value Back Benefits Reward Benefits Fuel Surcharge Waiver Other Benefits | C20: Pass | D20: Pass | E20: Pass | F20: 46329
A21: Etihad Guest SBI Premier Card | B21: Welcome Benefits Renewal Benefits Milestone Benefits Spend-Based Fee Reversal Insurance International Lounge Benefits Domestic Lounge Benefits Fuel Surcharge Waiver | C21: Fail | D21: Fail | E21: Fail | F21: 13/03/2026 | G21: 13/03/2026 - The renewal benefits icons is now other benefits icon - https://loom.com/i/9989e3e8db674b35aeeebe34cbd02074
